<robot
  name="AMAC_car_assy_9pm">
  <link
    name="base_link">
    <inertial>
      <origin
        xyz="0.023032 8.3678E-05 0.086547"
        rpy="0 0 0" />
      <mass
        value="4.148" />
      <inertia
        ixx="0.0030522"
        ixy="-4.7085E-06"
        ixz="-0.00050522"
        iyy="0.0064829"
        iyz="-2.7467E-05"
        izz="0.0034608" />
    </inertial>
    <visual>
      <origin
        xyz="0 0 0"
        rpy="0 0 0" />
      <geometry>
        <mesh
          filename="package://AMAC_car_assy_9pm/meshes/base_link.STL" />
      </geometry>
      <material
        name="">
        <color
          rgba="1 1 1 1" />
      </material>
    </visual>
    <collision>
      <origin
        xyz="0 0 0"
        rpy="0 0 0" />
      <geometry>
        <mesh
          filename="package://AMAC_car_assy_9pm/meshes/base_link.STL" />
      </geometry>
    </collision>
  </link>
  <link
    name="RF_wheel_turn">
    <inertial>
      <origin
        xyz="4.996E-16 0.0080683 -9.6728E-15"
        rpy="0 0 0" />
      <mass
        value="0.052985" />
      <inertia
        ixx="0"
        ixy="0"
        ixz="0"
        iyy="0"
        iyz="0"
        izz="0" />
    </inertial>
    <visual>
      <origin
        xyz="0 0 0"
        rpy="0 0 0" />
      <geometry>
        <mesh
          filename="package://AMAC_car_assy_9pm/meshes/RF_wheel_turn.STL" />
      </geometry>
      <material
        name="">
        <color
          rgba="0.29804 0.29804 0.29804 1" />
      </material>
    </visual>
    <collision>
      <origin
        xyz="0 0 0"
        rpy="0 0 0" />
      <geometry>
        <mesh
          filename="package://AMAC_car_assy_9pm/meshes/RF_wheel_turn.STL" />
      </geometry>
    </collision>
  </link>
  <joint
    name="right_turn_rev"
    type="revolute">
    <origin
      xyz="0.17938 -0.145 0.05762"
      rpy="-2.7214E-16 0 0" />
    <parent
      link="base_link" />
    <child
      link="RF_wheel_turn" />
    <axis
      xyz="0 0 1" />
    <limit
      lower="-1.5"
      upper="1.5"
      effort="0"
      velocity="0" />
  </joint>
  <link
    name="RF_wheel">
    <inertial>
      <origin
        xyz="4.996E-16 0.0080683 -9.6746E-15"
        rpy="0 0 0" />
      <mass
        value="0.052985" />
      <inertia
        ixx="0"
        ixy="0"
        ixz="0"
        iyy="0"
        iyz="0"
        izz="0" />
    </inertial>
    <visual>
      <origin
        xyz="0 0 0"
        rpy="0 0 0" />
      <geometry>
        <mesh
          filename="package://AMAC_car_assy_9pm/meshes/RF_wheel.STL" />
      </geometry>
      <material
        name="">
        <color
          rgba="0.29804 0.29804 0.29804 1" />
      </material>
    </visual>
    <collision>
      <origin
        xyz="0 0 0"
        rpy="0 0 0" />
      <geometry>
        <mesh
          filename="package://AMAC_car_assy_9pm/meshes/RF_wheel.STL" />
      </geometry>
    </collision>
  </link>
  <joint
    name="RF_wheel_cont"
    type="continuous">
    <origin
      xyz="0 0 0"
      rpy="-3.9618E-37 0 0" />
    <parent
      link="RF_wheel_turn" />
    <child
      link="RF_wheel" />
    <axis
      xyz="0 1 0" />
    <limit
      effort="0"
      velocity="100" />
  </joint>
  <link
    name="LF_wheel_turn">
    <inertial>
      <origin
        xyz="-5.5511E-16 -0.0080683 -7.2824E-15"
        rpy="0 0 0" />
      <mass
        value="0.052985" />
      <inertia
        ixx="0"
        ixy="0"
        ixz="0"
        iyy="0"
        iyz="0"
        izz="0" />
    </inertial>
    <visual>
      <origin
        xyz="0 0 0"
        rpy="0 0 0" />
      <geometry>
        <mesh
          filename="package://AMAC_car_assy_9pm/meshes/LF_wheel_turn.STL" />
      </geometry>
      <material
        name="">
        <color
          rgba="0.29804 0.29804 0.29804 1" />
      </material>
    </visual>
    <collision>
      <origin
        xyz="0 0 0"
        rpy="0 0 0" />
      <geometry>
        <mesh
          filename="package://AMAC_car_assy_9pm/meshes/LF_wheel_turn.STL" />
      </geometry>
    </collision>
  </link>
  <joint
    name="left_turn_rev"
    type="revolute">
    <origin
      xyz="0.17938 0.145 0.05762"
      rpy="-2.7214E-16 0 0" />
    <parent
      link="base_link" />
    <child
      link="LF_wheel_turn" />
    <axis
      xyz="0 0 1" />
    <limit
      lower="-1.5"
      upper="1.5"
      effort="0"
      velocity="0" />
  </joint>
  <link
    name="LF_wheel">
    <inertial>
      <origin
        xyz="-5.5511E-16 -0.0080683 -7.2824E-15"
        rpy="0 0 0" />
      <mass
        value="0.052985" />
      <inertia
        ixx="0"
        ixy="0"
        ixz="0"
        iyy="0"
        iyz="0"
        izz="0" />
    </inertial>
    <visual>
      <origin
        xyz="0 0 0"
        rpy="0 0 0" />
      <geometry>
        <mesh
          filename="package://AMAC_car_assy_9pm/meshes/LF_wheel.STL" />
      </geometry>
      <material
        name="">
        <color
          rgba="0.29804 0.29804 0.29804 1" />
      </material>
    </visual>
    <collision>
      <origin
        xyz="0 0 0"
        rpy="0 0 0" />
      <geometry>
        <mesh
          filename="package://AMAC_car_assy_9pm/meshes/LF_wheel.STL" />
      </geometry>
    </collision>
  </link>
  <joint
    name="LF_wheel_cont"
    type="continuous">
    <origin
      xyz="0 0 0"
      rpy="-3.9618E-37 0 0" />
    <parent
      link="LF_wheel_turn" />
    <child
      link="LF_wheel" />
    <axis
      xyz="0 1 0" />
    <limit
      effort="0"
      velocity="100" />
  </joint>
  <link
    name="RB_wheel">
    <inertial>
      <origin
        xyz="2.3245E-16 0.0080683 -8.1879E-16"
        rpy="0 0 0" />
      <mass
        value="0.052985" />
      <inertia
        ixx="0"
        ixy="0"
        ixz="0"
        iyy="0"
        iyz="0"
        izz="0" />
    </inertial>
    <visual>
      <origin
        xyz="0 0 0"
        rpy="0 0 0" />
      <geometry>
        <mesh
          filename="package://AMAC_car_assy_9pm/meshes/RB_wheel.STL" />
      </geometry>
      <material
        name="">
        <color
          rgba="0.29804 0.29804 0.29804 1" />
      </material>
    </visual>
    <collision>
      <origin
        xyz="0 0 0"
        rpy="0 0 0" />
      <geometry>
        <mesh
          filename="package://AMAC_car_assy_9pm/meshes/RB_wheel.STL" />
      </geometry>
    </collision>
  </link>
  <joint
    name="RB_wheel_cont"
    type="continuous">
    <origin
      xyz="-0.13862 -0.145 0.05762"
      rpy="-2.7214E-16 0 0" />
    <parent
      link="base_link" />
    <child
      link="RB_wheel" />
    <axis
      xyz="0 1 0" />
    <limit
      effort="0"
      velocity="100" />
  </joint>
  <link
    name="LB_wheel">
    <inertial>
      <origin
        xyz="-3.8164E-17 -0.0080683 1.7104E-15"
        rpy="0 0 0" />
      <mass
        value="0.052985" />
      <inertia
        ixx="0"
        ixy="0"
        ixz="0"
        iyy="0"
        iyz="0"
        izz="0" />
    </inertial>
    <visual>
      <origin
        xyz="0 0 0"
        rpy="0 0 0" />
      <geometry>
        <mesh
          filename="package://AMAC_car_assy_9pm/meshes/LB_wheel.STL" />
      </geometry>
      <material
        name="">
        <color
          rgba="0.29804 0.29804 0.29804 1" />
      </material>
    </visual>
    <collision>
      <origin
        xyz="0 0 0"
        rpy="0 0 0" />
      <geometry>
        <mesh
          filename="package://AMAC_car_assy_9pm/meshes/LB_wheel.STL" />
      </geometry>
    </collision>
  </link>
  <joint
    name="LB_wheel_cont"
    type="continuous">
    <origin
      xyz="-0.13862 0.145 0.05762"
      rpy="-2.7214E-16 -1.1102E-16 -4.9304E-32" />
    <parent
      link="base_link" />
    <child
      link="LB_wheel" />
    <axis
      xyz="0 1 0" />
    <limit
      effort="0"
      velocity="100" />
  </joint>
  <link
    name="lidar_base">
    <inertial>
      <origin
        xyz="0 5.5305E-16 0.030288"
        rpy="0 0 0" />
      <mass
        value="0.45597" />
      <inertia
        ixx="0"
        ixy="0"
        ixz="0"
        iyy="0"
        iyz="0"
        izz="0" />
    </inertial>
    <visual>
      <origin
        xyz="0 0 0"
        rpy="0 0 0" />
      <geometry>
        <mesh
          filename="package://AMAC_car_assy_9pm/meshes/lidar_base.STL" />
      </geometry>
      <material
        name="">
        <color
          rgba="0.65882 0.61961 0.56078 1" />
      </material>
    </visual>
    <collision>
      <origin
        xyz="0 0 0"
        rpy="0 0 0" />
      <geometry>
        <mesh
          filename="package://AMAC_car_assy_9pm/meshes/lidar_base.STL" />
      </geometry>
    </collision>
  </link>
  <joint
    name="lidar_base_fix"
    type="fixed">
    <origin
      xyz="-0.045 6.0708E-05 0.18324"
      rpy="1.3989E-32 -4.4411E-16 -1.6092E-16" />
    <parent
      link="base_link" />
    <child
      link="lidar_base" />
    <axis
      xyz="0 0 0" />
  </joint>
  <link
    name="IMU_base">
    <inertial>
      <origin
        xyz="-0.0005061 0.0026764 -0.0095809"
        rpy="0 0 0" />
      <mass
        value="0.010464" />
      <inertia
        ixx="3.6973E-07"
        ixy="6.2867E-08"
        ixz="5.3981E-10"
        iyy="2.7656E-07"
        iyz="2.4781E-09"
        izz="4.1597E-07" />
    </inertial>
    <visual>
      <origin
        xyz="0 0 0"
        rpy="0 0 0" />
      <geometry>
        <mesh
          filename="package://AMAC_car_assy_9pm/meshes/IMU_base.STL" />
      </geometry>
      <material
        name="">
        <color
          rgba="1 1 1 1" />
      </material>
    </visual>
    <collision>
      <origin
        xyz="0 0 0"
        rpy="0 0 0" />
      <geometry>
        <mesh
          filename="package://AMAC_car_assy_9pm/meshes/IMU_base.STL" />
      </geometry>
    </collision>
  </link>
  <joint
    name="IMU_base_fix"
    type="fixed">
    <origin
      xyz="0.15533 -0.00345 0.18733"
      rpy="-2.7214E-16 -1.6657E-16 1.901E-16" />
    <parent
      link="base_link" />
    <child
      link="IMU_base" />
    <axis
      xyz="1 0 0" />
  </joint>
  <link
    name="left_cam">
    <inertial>
      <origin
        xyz="0.00017008 -4.1479E-05 0.0037129"
        rpy="0 0 0" />
      <mass
        value="0.0057446" />
      <inertia
        ixx="0"
        ixy="0"
        ixz="0"
        iyy="0"
        iyz="0"
        izz="0" />
    </inertial>
    <visual>
      <origin
        xyz="0 0 0"
        rpy="0 0 0" />
      <geometry>
        <mesh
          filename="package://AMAC_car_assy_9pm/meshes/left_cam.STL" />
      </geometry>
      <material
        name="">
        <color
          rgba="0.79216 0.81961 0.93333 1" />
      </material>
    </visual>
    <collision>
      <origin
        xyz="0 0 0"
        rpy="0 0 0" />
      <geometry>
        <mesh
          filename="package://AMAC_car_assy_9pm/meshes/left_cam.STL" />
      </geometry>
    </collision>
  </link>
  <joint
    name="left_cam_fix"
    type="fixed">
    <origin
      xyz="0.2308 0.053407 0.14724"
      rpy="1.5708 1.2163E-15 2.2689" />
    <parent
      link="base_link" />
    <child
      link="left_cam" />
    <axis
      xyz="0 0 0" />
  </joint>
  <link
    name="mid_cam">
    <inertial>
      <origin
        xyz="0.00017008 -4.1478E-05 0.0037129"
        rpy="0 0 0" />
      <mass
        value="0.0057446" />
      <inertia
        ixx="0"
        ixy="0"
        ixz="0"
        iyy="0"
        iyz="0"
        izz="0" />
    </inertial>
    <visual>
      <origin
        xyz="0 0 0"
        rpy="0 0 0" />
      <geometry>
        <mesh
          filename="package://AMAC_car_assy_9pm/meshes/mid_cam.STL" />
      </geometry>
      <material
        name="">
        <color
          rg