<robot
  name="car_amac">
  <link
    name="lidar_base_link">
    <inertial>
      <origin
        xyz="0.06072 0.0001453 -0.06777"
        rpy="0 0 0" />
      <mass
        value="2.1016" />
      <inertia
        ixx="0.0051834"
        ixy="-6.6304E-06"
        ixz="0.001372"
        iyy="0.0096466"
        iyz="-1.5998E-05"
        izz="0.0044931" />
    </inertial>
    <visual>
      <origin
        xyz="0 0 0"
        rpy="0 0 0" />
      <geometry>
        <mesh
          filename="package://car_amac/meshes/lidar_base_link.STL" />
      </geometry>
      <material
        name="">
        <color
          rgba="0.89412 0.91373 0.92941 1" />
      </material>
    </visual>
    <collision>
      <origin
        xyz="0 0 0"
        rpy="0 0 0" />
      <geometry>
        <mesh
          filename="package://car_amac/meshes/lidar_base_link.STL" />
      </geometry>
    </collision>
  </link>
  <link
    name="LB_wheel">
    <inertial>
      <origin
        xyz="-1.7587E-09 -0.0058606 -3.4889E-10"
        rpy="0 0 0" />
      <mass
        value="0.09432" />
      <inertia
        ixx="0"
        ixy="0"
        ixz="0"
        iyy="0"
        iyz="0"
        izz="0" />
    </inertial>
    <visual>
      <origin
        xyz="0 0 0"
        rpy="0 0 0" />
      <geometry>
        <mesh
          filename="package://car_amac/meshes/LB_wheel.STL" />
      </geometry>
      <material
        name="">
        <color
          rgba="0.79216 0.81961 0.93333 1" />
      </material>
    </visual>
    <collision>
      <origin
        xyz="0 0 0"
        rpy="0 0 0" />
      <geometry>
        <mesh
          filename="package://car_amac/meshes/LB_wheel.STL" />
      </geometry>
    </collision>
  </link>
  <joint
    name="LB_wheel_cont"
    type="continuous">
    <origin
      xyz="-0.093466 0.145 -0.12113"
      rpy="-1.2694E-14 1.483E-15 2.2413E-15" />
    <parent
      link="lidar_base_link" />
    <child
      link="LB_wheel" />
    <axis
      xyz="0 1 0" />
  </joint>
  <link
    name="RB_wheel">
    <inertial>
      <origin
        xyz="-1.0738E-11 0.0058606 -1.793E-09"
        rpy="0 0 0" />
      <mass
        value="0.09432" />
      <inertia
        ixx="0"
        ixy="0"
        ixz="0"
        iyy="0"
        iyz="0"
        izz="0" />
    </inertial>
    <visual>
      <origin
        xyz="0 0 0"
        rpy="0 0 0" />
      <geometry>
        <mesh
          filename="package://car_amac/meshes/RB_wheel.STL" />
      </geometry>
      <material
        name="">
        <color
          rgba="0.79216 0.81961 0.93333 1" />
      </material>
    </visual>
    <collision>
      <origin
        xyz="0 0 0"
        rpy="0 0 0" />
      <geometry>
        <mesh
          filename="package://car_amac/meshes/RB_wheel.STL" />
      </geometry>
    </collision>
  </link>
  <joint
    name="RB_wheel_cont"
    type="continuous">
    <origin
      xyz="-0.093466 -0.145 -0.12113"
      rpy="-1.2694E-14 1.483E-15 2.2413E-15" />
    <parent
      link="lidar_base_link" />
    <child
      link="RB_wheel" />
    <axis
      xyz="0 1 0" />
  </joint>
  <link
    name="LF_wheel">
    <inertial>
      <origin
        xyz="-1.2145E-09 -0.0058606 -1.3191E-09"
        rpy="0 0 0" />
      <mass
        value="0.09432" />
      <inertia
        ixx="0"
        ixy="0"
        ixz="0"
        iyy="0"
        iyz="0"
        izz="0" />
    </inertial>
    <visual>
      <origin
        xyz="0 0 0"
        rpy="0 0 0" />
      <geometry>
        <mesh
          filename="package://car_amac/meshes/LF_wheel.STL" />
      </geometry>
      <material
        name="">
        <color
          rgba="0.79216 0.81961 0.93333 1" />
      </material>
    </visual>
    <collision>
      <origin
        xyz="0 0 0"
        rpy="0 0 0" />
      <geometry>
        <mesh
          filename="package://car_amac/meshes/LF_wheel.STL" />
      </geometry>
    </collision>
  </link>
  <joint
    name="LF_wheel_cont"
    type="continuous">
    <origin
      xyz="0.22421 0.145 -0.12113"
      rpy="-1.2694E-14 1.483E-15 2.2413E-15" />
    <parent
      link="lidar_base_link" />
    <child
      link="LF_wheel" />
    <axis
      xyz="0 1 0" />
  </joint>
  <link
    name="RF_wheel">
    <inertial>
      <origin
        xyz="-1.5057E-09 0.0058606 -9.735E-10"
        rpy="0 0 0" />
      <mass
        value="0.09432" />
      <inertia
        ixx="0"
        ixy="0"
        ixz="0"
        iyy="0"
        iyz="0"
        izz="0" />
    </inertial>
    <visual>
      <origin
        xyz="0 0 0"
        rpy="0 0 0" />
      <geometry>
        <mesh
          filename="package://car_amac/meshes/RF_wheel.STL" />
      </geometry>
      <material
        name="">
        <color
          rgba="0.79216 0.81961 0.93333 1" />
      </material>
    </visual>
    <collision>
      <origin
        xyz="0 0 0"
        rpy="0 0 0" />
      <geometry>
        <mesh
          filename="package://car_amac/meshes/RF_wheel.STL" />
      </geometry>
    </collision>
  </link>
  <joint
    name="RF_wheel_cont"
    type="continuous">
    <origin
      xyz="0.22421 -0.145 -0.12113"
      rpy="-1.2694E-14 1.483E-15 2.2413E-15" />
    <parent
      link="lidar_base_link" />
    <child
      link="RF_wheel" />
    <axis
      xyz="0 1 0" />
  </joint>
</robot>