<robot
  name="AMAC_car_assy_9pm2">
  <link
    name="base_link">
    <inertial>
      <origin
        xyz="0.166025978689335 0.107880342028048 0.0114040478505038"
        rpy="0 0 0" />
      <mass
        value="4.14800954871025" />
      <inertia
        ixx="0.0378468989497725"
        ixy="-0.0437315713488928"
        ixz="-0.0182482465235077"
        iyy="0.0995731025001106"
        iyz="-0.00850601840420408"
        izz="0.108939176688436" />
    </inertial>
    <visual>
      <origin
        xyz="0 0 0"
        rpy="0 0 0" />
      <geometry>
        <mesh
          filename="package://AMAC_car_assy_9pm2/meshes/base_link.STL" />
      </geometry>
      <material
        name="">
        <color
          rgba="1 1 1 1" />
      </material>
    </visual>
    <collision>
      <origin
        xyz="0 0 0"
        rpy="0 0 0" />
      <geometry>
        <mesh
          filename="package://AMAC_car_assy_9pm2/meshes/base_link.STL" />
      </geometry>
    </collision>
  </link>
  <link
    name="RF_wheel_turn">
    <inertial>
      <origin
        xyz="-1.23126955228344 -0.549882978478997 -0.394771389019161"
        rpy="0 0 0" />
      <mass
        value="0.0529847952512973" />
      <inertia
        ixx="0"
        ixy="0"
        ixz="0"
        iyy="0"
        iyz="0"
        izz="0" />
    </inertial>
    <visual>
      <origin
        xyz="0 0 0"
        rpy="0 0 0" />
      <geometry>
        <mesh
          filename="package://AMAC_car_assy_9pm2/meshes/RF_wheel_turn.STL" />
      </geometry>
      <material
        name="">
        <color
          rgba="0.298039215686275 0.298039215686275 0.298039215686275 1" />
      </material>
    </visual>
    <collision>
      <origin
        xyz="0 0 0"
        rpy="0 0 0" />
      <geometry>
        <mesh
          filename="package://AMAC_car_assy_9pm2/meshes/RF_wheel_turn.STL" />
      </geometry>
    </collision>
  </link>
  <joint
    name="right_turn_rev"
    type="revolute">
    <origin
      xyz="0.17938 -0.145 0.05762"
      rpy="-2.7214E-16 0 0" />
    <parent
      link="base_link" />
    <child
      link="RF_wheel_turn" />
    <axis
      xyz="1 0 0" />
    <limit
      effort="0"
      velocity="0" />
  </joint>
  <link
    name="RF_wheel">
    <inertial>
      <origin
        xyz="-1.23126955228344 -0.549882978478998 -0.394771389019161"
        rpy="0 0 0" />
      <mass
        value="0.0529847952512974" />
      <inertia
        ixx="0"
        ixy="0"
        ixz="0"
        iyy="0"
        iyz="0"
        izz="0" />
    </inertial>
    <visual>
      <origin
        xyz="0 0 0"
        rpy="0 0 0" />
      <geometry>
        <mesh
          filename="package://AMAC_car_assy_9pm2/meshes/RF_wheel.STL" />
      </geometry>
      <material
        name="">
        <color
          rgba="0.298039215686275 0.298039215686275 0.298039215686275 1" />
      </material>
    </visual>
    <collision>
      <origin
        xyz="0 0 0"
        rpy="0 0 0" />
      <geometry>
        <mesh
          filename="package://AMAC_car_assy_9pm2/meshes/RF_wheel.STL" />
      </geometry>
    </collision>
  </link>
  <joint
    name="RF_wheel_cont"
    type="continuous">
    <origin
      xyz="0 0 0"
      rpy="-3.9618E-37 0 0" />
    <parent
      link="RF_wheel_turn" />
    <child
      link="RF_wheel" />
    <axis
      xyz="0 1 0" />
  </joint>
  <link
    name="LF_wheel_turn">
    <inertial>
      <origin
        xyz="-0.545472943612066 0.549882978478996 -1.17231754561448"
        rpy="0 0 0" />
      <mass
        value="0.0529847952513019" />
      <inertia
        ixx="0"
        ixy="0"
        ixz="0"
        iyy="0"
        iyz="0"
        izz="0" />
    </inertial>
    <visual>
      <origin
        xyz="0 0 0"
        rpy="0 0 0" />
      <geometry>
        <mesh
          filename="package://AMAC_car_assy_9pm2/meshes/LF_wheel_turn.STL" />
      </geometry>
      <material
        name="">
        <color
          rgba="0.298039215686275 0.298039215686275 0.298039215686275 1" />
      </material>
    </visual>
    <collision>
      <origin
        xyz="0 0 0"
        rpy="0 0 0" />
      <geometry>
        <mesh
          filename="package://AMAC_car_assy_9pm2/meshes/LF_wheel_turn.STL" />
      </geometry>
    </collision>
  </link>
  <joint
    name="left_turn_rev"
    type="revolute">
    <origin
      xyz="0.179375934223985 0.145000000000001 0.0576199999999994"
      rpy="-2.72136117822989E-16 0 0" />
    <parent
      link="base_link" />
    <child
      link="LF_wheel_turn" />
    <axis
      xyz="1 0 0" />
  </joint>
  <link
    name="LF_wheel">
    <inertial>
      <origin
        xyz="-0.545472943612066 0.549882978478996 -1.17231754561448"
        rpy="0 0 0" />
      <mass
        value="0.052984795251302" />
      <inertia
        ixx="0"
        ixy="0"
        ixz="0"
        iyy="0"
        iyz="0"
        izz="0" />
    </inertial>
    <visual>
      <origin
        xyz="0 0 0"
        rpy="0 0 0" />
      <geometry>
        <mesh
          filename="package://AMAC_car_assy_9pm2/meshes/LF_wheel.STL" />
      </geometry>
      <material
        name="">
        <color
          rgba="0.298039215686275 0.298039215686275 0.298039215686275 1" />
      </material>
    </visual>
    <collision>
      <origin
        xyz="0 0 0"
        rpy="0 0 0" />
      <geometry>
        <mesh
          filename="package://AMAC_car_assy_9pm2/meshes/LF_wheel.STL" />
      </geometry>
    </collision>
  </link>
  <joint
    name="LF_wheel_cont"
    type="continuous">
    <origin
      xyz="0 0 0"
      rpy="-3.96178014104341E-37 0 0" />
    <parent
      link="LF_wheel_turn" />
    <child
      link="LF_wheel" />
    <axis
      xyz="0 1 0" />
  </joint>
  <link
    name="RB_wheel">
    <inertial>
      <origin
        xyz="1.15333843357393 -0.549882978478998 0.584533675342648"
        rpy="0 0 0" />
      <mass
        value="0.0529847952512978" />
      <inertia
        ixx="0"
        ixy="0"
        ixz="0"
        iyy="0"
        iyz="0"
        izz="0" />
    </inertial>
    <visual>
      <origin
        xyz="0 0 0"
        rpy="0 0 0" />
      <geometry>
        <mesh
          filename="package://AMAC_car_assy_9pm2/meshes/RB_wheel.STL" />
      </geometry>
      <material
        name="">
        <color
          rgba="0.298039215686275 0.298039215686275 0.298039215686275 1" />
      </material>
    </visual>
    <collision>
      <origin
        xyz="0 0 0"
        rpy="0 0 0" />
      <geometry>
        <mesh
          filename="package://AMAC_car_assy_9pm2/meshes/RB_wheel.STL" />
      </geometry>
    </collision>
  </link>
  <joint
    name="RB_wheel_cont"
    type="continuous">
    <origin
      xyz="-0.138624065776015 -0.144999999999999 0.0576199999999995"
      rpy="-2.72136117822989E-16 0 0" />
    <parent
      link="base_link" />
    <child
      link="RB_wheel" />
    <axis
      xyz="0 1 0" />
  </joint>
  <link
    name="LB_wheel">
    <inertial>
      <origin
        xyz="0.757440785926755 0.549882978478998 -1.04792777221668"
        rpy="0 0 0" />
      <mass
        value="0.0529847952512874" />
      <inertia
        ixx="0"
        ixy="0"
        ixz="0"
        iyy="0"
        iyz="0"
        izz="0" />
    </inertial>
    <visual>
      <origin
        xyz="0 0 0"
        rpy="0 0 0" />
      <geometry>
        <mesh
          filename="package://AMAC_car_assy_9pm2/meshes/LB_wheel.STL" />
      </geometry>
      <material
        name="">
        <color
          rgba="0.298039215686275 0.298039215686275 0.298039215686275 1" />
      </material>
    </visual>
    <collision>
      <origin
        xyz="0 0 0"
        rpy="0 0 0" />
      <geometry>
        <mesh
          filename="package://AMAC_car_assy_9pm2/meshes/LB_wheel.STL" />
      </geometry>
    </collision>
  </link>
  <joint
    name="LB_wheel_cont"
    type="continuous">
    <origin
      xyz="-0.138624065776015 0.145000000000001 0.0576199999999994"
      rpy="-2.72136117822989E-16 -1.11022302462516E-16 -4.93038065763132E-32" />
    <parent
      link="base_link" />
    <child
      link="LB_wheel" />
    <axis
      xyz="0 1 0" />
  </joint>
  <link
    name="lidar_base">
    <inertial>
      <origin
        xyz="-0.11740993783226 -0.168797654529726 -0.0833775843586243"
        rpy="0 0 0" />
      <mass
        value="0.455970555213361" />
      <inertia
        ixx="0"
        ixy="0"
        ixz="0"
        iyy="0"
        iyz="0"
        izz="0" />
    </inertial>
    <visual>
      <origin
        xyz="0 0 0"
        rpy="0 0 0" />
      <geometry>
        <mesh
          filename="package://AMAC_car_assy_9pm2/meshes/lidar_base.STL" />
      </geometry>
      <material
        name="">
        <color
          rgba="0.658823529411765 0.619607843137255 0.56078431372549 1" />
      </material>
    </visual>
    <collision>
      <origin
        xyz="0 0 0"
        rpy="0 0 0" />
      <geometry>
        <mesh
          filename="package://AMAC_car_assy_9pm2/meshes/lidar_base.STL" />
      </geometry>
    </collision>
  </link>
  <joint
    name="lidar_base_fix"
    type="fixed">
    <origin
      xyz="-0.045 6.0707851028269E-05 0.18324"
      rpy="1.39890124957013E-32 -4.44109895871787E-16 -1.60920486383744E-16" />
    <parent
      link="base_link" />
    <child
      link="lidar_base" />
    <axis
      xyz="0 0 0" />
  </joint>
  <link
    name="IMU_base">
    <inertial>
      <origin
        xyz="-0.39959 0.12006 -0.29451"
        rpy="0 0 0" />
      <mass
        value="0.010464" />
      <inertia
        ixx="4.1597E-07"
        ixy="-5.3981E-10"
        ixz="-2.4781E-09"
        iyy="3.6973E-07"
        iyz="6.2867E-08"
        izz="2.7656E-07" />
    </inertial>
    <visual>
      <origin
        xyz="0 0 0"
        rpy="0 0 0" />
      <geometry>
        <mesh
          filename="package://AMAC_car_assy_9pm2/meshes/IMU_base.STL" />
      </geometry>
      <material
        name="">
        <color
          rgba="1 1 1 1" />
      </material>
    </visual>
    <collision>
      <origin
        xyz="0 0 0"
        rpy="0 0 0" />
      <geometry>
        <mesh
          filename="package://AMAC_car_assy_9pm2/meshes/IMU_base.STL" />
      </geometry>
    </collision>
  </link>
  <joint
    name="IMU_base_fix"
    type="fixed">
    <origin
      xyz="0.155326383380844 -0.00344999989920807 0.1873276"
      rpy="-2.72136117822987E-16 -1.66574825737217E-16 1.90098110802259E-16" />
    <parent
      link="base_link" />
    <child
      link="IMU_base" />
    <axis
      xyz="0 0 0" />
  </joint>
  <link
    name="left_cam">
    <inertial>
      <origin
        xyz="-0.96873 -0.48253 -1.9072"
        rpy="0 0 0" />
      <mass
        value="0.0057446" />
      <inertia
        ixx="0"
        ixy="0"
        ixz="0"
        iyy="0"
        iyz="0"
        izz="0" />
    </inertial>
    <visual>
      <origin
        xyz="0 0 0"
        rpy="0 0 0" />
      <geometry>
        <mesh
          filename="package://AMAC_car_assy_9pm2/meshes/left_cam.STL" />
      </geometry>
      <material
        name="">
        <color
          rgba="0.79216 0.81961 0.93333 1" />
      </material>
    </visual>
    <collision>
      <origin
        xyz="0 0 0"
        rpy="0 0 0" />
      <geometry>
        <mesh
          filename="package://AMAC_car_assy_9pm2/meshes/left_cam.STL" />
      </geometry>
    </collision>
  </link>
  <joint
    name="left_cam_fix"
    type="fixed">
    <origin
      xyz="0.2308 0.053407 0.14724"
      rpy="1.5708 1.2163E-15 2.2689" />
    <parent
      link="base_link" />
    <child
      link="left_cam" />
    <axis
      xyz="0 0 0" />
  </joint>
  <link
    name="mid_cam">
    <inertial>
      <origin
        xyz="-0.96873 -0.48253 -1.9072"
        rpy="0 0 0" />
      <mass
        value="0.0057446" />
      <inertia
        ixx="0"
        ixy="0"
        ixz="0"
        iyy="0"
        iyz="0"
        izz="0" />
    </inertial>
    <visual>
      <origin
        xyz="0 0 0"
        rpy="0 0 0" />
      <geometry>
        <mesh
          filename="package://AMAC_car_assy_9pm2/meshes/mid_cam.STL" />
      </geometry>
      <material
        name="">
        <color
          rgba="0.79216 0.81961 0.93333 1" />
      </material>
    </visual>
    <collision>
      <origin
        xyz="0 0 0"
        rpy="0 0 0" />
      <geometry>
        <mesh
          filename="package://AMAC_car_assy_9pm2/meshes/mid_cam.STL" />
      </geometry>
    </collision>
  </link>
  <joint
    name="mid_cam_fix"
    type="fixed">
    <origin
      xyz="0.24638 0.00035411 0.14724"
      rpy="1.5708 2.7212E-16 1.5708" />
    <parent
      link="base_link" />
    <child
      link="mid_cam" />
    <axis
      xyz="0 0 0" />
  </joint>
  <link
    name="right_cam">
    <inertial>
      <origin
        xyz="-0.96873 -0.48253 -1.9072"
        rpy="0 0 0" />
      <mass
        value="0.0057446" />
      <inertia
        ixx="0"
        ixy="0"
        ixz="0"
        iyy="0"
        iyz="0"
        izz="0" />
    </inertial>
    <visual>
      <origin
        xyz="0 0 0"
        rpy="0 0 0" />
      <geometry>
        <mesh
          filename="package://AMAC_car_assy_9pm2/meshes/right_cam.STL" />
      </geometry>
      <material
        name="">
        <color
          rgba="0.79216 0.81961 0.93333 1" />
      </material>
    </visual>
    <collision>
      <origin
        xyz="0 0 0"
        rpy="0 0 0" />
      <geometry>
        <mesh
          filename="package://AMAC_car_assy_9pm2/meshes/right_cam.STL" />
      </geometry>
    </collision>
  </link>
  <joint
    name="right_cam_fix"
    type="fixed">
    <origin
      xyz="0.23088 -0.053472 0.14724"
      rpy="1.5708 1.886E-15 0.87266" />
    <parent
      link="base_link" />
    <child
      link="right_cam" />
    <axis
      xyz="0 0 0" />
  </joint>
</robot>