<robot
  name="AMAC_car_assy">
  <link
    name="lidar_base_link">
    <inertial>
      <origin
        xyz="0.061533 0.00010305 -0.070717"
        rpy="0 0 0" />
      <mass
        value="2.2023" />
      <inertia
        ixx="0.0055245"
        ixy="-6.0021E-06"
        ixz="0.0014485"
        iyy="0.010002"
        iyz="-2.0031E-05"
        izz="0.0045076" />
    </inertial>
    <visual>
      <origin
        xyz="0 0 0"
        rpy="0 0 0" />
      <geometry>
        <mesh
          filename="package://AMAC_car_assy/meshes/lidar_base_link.STL" />
      </geometry>
      <material
        name="">
        <color
          rgba="0.89412 0.91373 0.92941 1" />
      </material>
    </visual>
    <collision>
      <origin
        xyz="0 0 0"
        rpy="0 0 0" />
      <geometry>
        <mesh
          filename="package://AMAC_car_assy/meshes/lidar_base_link.STL" />
      </geometry>
    </collision>
  </link>
  <link
    name="LB_wheel">
    <inertial>
      <origin
        xyz="-3.8164E-17 -0.0080683 1.7122E-15"
        rpy="0 0 0" />
      <mass
        value="0.052985" />
      <inertia
        ixx="0"
        ixy="0"
        ixz="0"
        iyy="0"
        iyz="0"
        izz="0" />
    </inertial>
    <visual>
      <origin
        xyz="0 0 0"
        rpy="0 0 0" />
      <geometry>
        <mesh
          filename="package://AMAC_car_assy/meshes/LB_wheel.STL" />
      </geometry>
      <material
        name="">
        <color
          rgba="0.79216 0.81961 0.93333 1" />
      </material>
    </visual>
    <collision>
      <origin
        xyz="0 0 0"
        rpy="0 0 0" />
      <geometry>
        <mesh
          filename="package://AMAC_car_assy/meshes/LB_wheel.STL" />
      </geometry>
    </collision>
  </link>
  <joint
    name="LB_wheel_cont"
    type="continuous">
    <origin
      xyz="-0.093624 0.14494 -0.12562"
      rpy="-2.7214E-16 3.3309E-16 1.6092E-16" />
    <parent
      link="lidar_base_link" />
    <child
      link="LB_wheel" />
    <axis
      xyz="0 1 0" />
    <limit
      effort="100"
      velocity="100" />
  </joint>
  <link
    name="RB_wheel">
    <inertial>
      <origin
        xyz="2.3245E-16 0.0080683 -8.2052E-16"
        rpy="0 0 0" />
      <mass
        value="0.052985" />
      <inertia
        ixx="0"
        ixy="0"
        ixz="0"
        iyy="0"
        iyz="0"
        izz="0" />
    </inertial>
    <visual>
      <origin
        xyz="0 0 0"
        rpy="0 0 0" />
      <geometry>
        <mesh
          filename="package://AMAC_car_assy/meshes/RB_wheel.STL" />
      </geometry>
      <material
        name="">
        <color
          rgba="0.79216 0.81961 0.93333 1" />
      </material>
    </visual>
    <collision>
      <origin
        xyz="0 0 0"
        rpy="0 0 0" />
      <geometry>
        <mesh
          filename="package://AMAC_car_assy/meshes/RB_wheel.STL" />
      </geometry>
    </collision>
  </link>
  <joint
    name="RB_wheel_cont"
    type="continuous">
    <origin
      xyz="-0.093624 -0.14506 -0.12562"
      rpy="-2.7214E-16 4.4411E-16 1.6092E-16" />
    <parent
      link="lidar_base_link" />
    <child
      link="RB_wheel" />
    <axis
      xyz="0 1 0" />
    <limit
      effort="100"
      velocity="100" />
  </joint>
  <link
    name="left_turn">
    <inertial>
      <origin
        xyz="-5.5511E-16 -0.0080683 -7.2806E-15"
        rpy="0 0 0" />
      <mass
        value="0.052985" />
      <inertia
        ixx="0"
        ixy="0"
        ixz="0"
        iyy="0"
        iyz="0"
        izz="0" />
    </inertial>
    <visual>
      <origin
        xyz="0 0 0"
        rpy="0 0 0" />
      <geometry>
        <mesh
          filename="package://AMAC_car_assy/meshes/left_turn.STL" />
      </geometry>
      <material
        name="">
        <color
          rgba="0.79216 0.81961 0.93333 1" />
      </material>
    </visual>
    <collision>
      <origin
        xyz="0 0 0"
        rpy="0 0 0" />
      <geometry>
        <mesh
          filename="package://AMAC_car_assy/meshes/left_turn.STL" />
      </geometry>
    </collision>
  </link>
  <joint
    name="left_turn_rev"
    type="revolute">
    <origin
      xyz="0.22438 0.14494 -0.12562"
      rpy="-2.7214E-16 4.4411E-16 1.6092E-16" />
    <parent
      link="lidar_base_link" />
    <child
      link="left_turn" />
    <axis
      xyz="0 0 1" />
    <limit
      lower="1"
      upper="2.1"
      effort="0"
      velocity="0" />
  </joint>
  <link
    name="LF_wheel">
    <inertial>
      <origin
        xyz="-5.5511E-16 -0.0080683 -7.2806E-15"
        rpy="0 0 0" />
      <mass
        value="0.052985" />
      <inertia
        ixx="0"
        ixy="0"
        ixz="0"
        iyy="0"
        iyz="0"
        izz="0" />
    </inertial>
    <visual>
      <origin
        xyz="0 0 0"
        rpy="0 0 0" />
      <geometry>
        <mesh
          filename="package://AMAC_car_assy/meshes/LF_wheel.STL" />
      </geometry>
      <material
        name="">
        <color
          rgba="0.79216 0.81961 0.93333 1" />
      </material>
    </visual>
    <collision>
      <origin
        xyz="0 0 0"
        rpy="0 0 0" />
      <geometry>
        <mesh
          filename="package://AMAC_car_assy/meshes/LF_wheel.STL" />
      </geometry>
    </collision>
  </link>
  <joint
    name="LF_wheel_cont"
    type="continuous">
    <origin
      xyz="0 0 0"
      rpy="-3.9618E-37 0 0" />
    <parent
      link="left_turn" />
    <child
      link="LF_wheel" />
    <axis
      xyz="0 1 0" />
    <limit
      effort="100"
      velocity="100" />
  </joint>
  <link
    name="right_turn">
    <inertial>
      <origin
        xyz="4.9960036108132E-16 0.00806826444733189 -9.67455282552265E-15"
        rpy="0 0 0" />
      <mass
        value="0.0529847952512966" />
      <inertia
        ixx="0"
        ixy="0"
        ixz="0"
        iyy="0"
        iyz="